Workbook

Sheet Cover & Instructions
B2: ERP — User Acceptance Test (UAT) Plan
B4: Purpose | C4: End-to-end UAT for the ERP, organised one tab per module. Each row is a manually-executable test case for the QA team. Fill in Actual Result, Status, Severity, Tester and Run Date as you go; the Summary tab tallies results live.
B5: Total test cases | C5: 696
B6: Modules / tabs | C6: 27
B7: Generated | C7: 2026-06-27
B8: QA environment | C8: https://16.170.11.41/ (QA stack; data is durable — do not expect a clean DB)
B9: Login | C9: Use a NON-root user with the relevant role for permission cases (root bypasses all permission checks and will mask RBAC defects). Switch branch via the top-bar branch picker where a test needs a specific branch.
B11: How to run a case | C11: 1) Read Preconditions and set them up. 2) Follow Steps in the app. 3) Compare what you see to Expected Result. 4) Put Pass/Fail/Blocked in Status; if Fail, write what happened in Actual Result, set Severity, and log it on the 'Defects Log' tab.
B13: Status values | C13: Not Run (default) · Pass · Fail · Blocked · N/A
B14: Severity (for fails) | C14: Critical (blocks a core flow / data loss) · High · Medium · Low (cosmetic)
B15: Type | C15: Positive (happy path) · Negative (rejection/validation) · Permission (RBAC) · Edge
B16: Priority | C16: High = must pass for sign-off · Medium · Low
B18: Column guide | C18: ID = stable case id · Area = feature · Route = where in the app · Permission = the RBAC code involved. 'Expected Result' is the pass criterion.
B19: Note | C19: Some cases intentionally document a KNOWN issue (look for 'DEFECT'/'known issue' in the scenario or expected text) — verify the stated current behaviour.

Sheet Summary
A1: UAT Summary Dashboard
A2: Module | B2: Cases | C2: Not Run | D2: Pass | E2: Fail | F2: Blocked | G2: N/A | H2: Pass %
A3: IAM & Access | B3: 47 | C3: =COUNTIF('IAM & Access'!$M$3:$M$100000,"Not Run") | D3: =COUNTIF('IAM & Access'!$M$3:$M$100000,"Pass") | E3: =COUNTIF('IAM & Access'!$M$3:$M$100000,"Fail") | F3: =COUNTIF('IAM & Access'!$M$3:$M$100000,"Blocked") | G3: =COUNTIF('IAM & Access'!$M$3:$M$100000,"N/A") | H3: =IFERROR(D3/(D3+E3),"")
A4: RBAC | B4: 20 | C4: =COUNTIF('RBAC'!$M$3:$M$100000,"Not Run") | D4: =COUNTIF('RBAC'!$M$3:$M$100000,"Pass") | E4: =COUNTIF('RBAC'!$M$3:$M$100000,"Fail") | F4: =COUNTIF('RBAC'!$M$3:$M$100000,"Blocked") | G4: =COUNTIF('RBAC'!$M$3:$M$100000,"N/A") | H4: =IFERROR(D4/(D4+E4),"")
A5: Platform – Documents | B5: 11 | C5: =COUNTIF('Platform – Documents'!$M$3:$M$100000,"Not Run") | D5: =COUNTIF('Platform – Documents'!$M$3:$M$100000,"Pass") | E5: =COUNTIF('Platform – Documents'!$M$3:$M$100000,"Fail") | F5: =COUNTIF('Platform – Documents'!$M$3:$M$100000,"Blocked") | G5: =COUNTIF('Platform – Documents'!$M$3:$M$100000,"N/A") | H5: =IFERROR(D5/(D5+E5),"")
A6: Platform – Notifications | B6: 7 | C6: =COUNTIF('Platform – Notifications'!$M$3:$M$100000,"Not Run") | D6: =COUNTIF('Platform – Notifications'!$M$3:$M$100000,"Pass") | E6: =COUNTIF('Platform – Notifications'!$M$3:$M$100000,"Fail") | F6: =COUNTIF('Platform – Notifications'!$M$3:$M$100000,"Blocked") | G6: =COUNTIF('Platform – Notifications'!$M$3:$M$100000,"N/A") | H6: =IFERROR(D6/(D6+E6),"")
A7: Platform – Approvals | B7: 17 | C7: =COUNTIF('Platform – Approvals'!$M$3:$M$100000,"Not Run") | D7: =COUNTIF('Platform – Approvals'!$M$3:$M$100000,"Pass") | E7: =COUNTIF('Platform – Approvals'!$M$3:$M$100000,"Fail") | F7: =COUNTIF('Platform – Approvals'!$M$3:$M$100000,"Blocked") | G7: =COUNTIF('Platform – Approvals'!$M$3:$M$100000,"N/A") | H7: =IFERROR(D7/(D7+E7),"")
A8: Platform – Audit | B8: 6 | C8: =COUNTIF('Platform – Audit'!$M$3:$M$100000,"Not Run") | D8: =COUNTIF('Platform – Audit'!$M$3:$M$100000,"Pass") | E8: =COUNTIF('Platform – Audit'!$M$3:$M$100000,"Fail") | F8: =COUNTIF('Platform – Audit'!$M$3:$M$100000,"Blocked") | G8: =COUNTIF('Platform – Audit'!$M$3:$M$100000,"N/A") | H8: =IFERROR(D8/(D8+E8),"")
A9: Conventions | B9: 31 | C9: =COUNTIF('Conventions'!$M$3:$M$100000,"Not Run") | D9: =COUNTIF('Conventions'!$M$3:$M$100000,"Pass") | E9: =COUNTIF('Conventions'!$M$3:$M$100000,"Fail") | F9: =COUNTIF('Conventions'!$M$3:$M$100000,"Blocked") | G9: =COUNTIF('Conventions'!$M$3:$M$100000,"N/A") | H9: =IFERROR(D9/(D9+E9),"")
A10: Masters – Parties | B10: 24 | C10: =COUNTIF('Masters – Parties'!$M$3:$M$100000,"Not Run") | D10: =COUNTIF('Masters – Parties'!$M$3:$M$100000,"Pass") | E10: =COUNTIF('Masters – Parties'!$M$3:$M$100000,"Fail") | F10: =COUNTIF('Masters – Parties'!$M$3:$M$100000,"Blocked") | G10: =COUNTIF('Masters – Parties'!$M$3:$M$100000,"N/A") | H10: =IFERROR(D10/(D10+E10),"")
A11: Masters – Catalog | B11: 20 | C11: =COUNTIF('Masters – Catalog'!$M$3:$M$100000,"Not Run") | D11: =COUNTIF('Masters – Catalog'!$M$3:$M$100000,"Pass") | E11: =COUNTIF('Masters – Catalog'!$M$3:$M$100000,"Fail") | F11: =COUNTIF('Masters – Catalog'!$M$3:$M$100000,"Blocked") | G11: =COUNTIF('Masters – Catalog'!$M$3:$M$100000,"N/A") | H11: =IFERROR(D11/(D11+E11),"")
A12: Sales – Order to Cash | B12: 43 | C12: =COUNTIF('Sales – Order to Cash'!$M$3:$M$100000,"Not Run") | D12: =COUNTIF('Sales – Order to Cash'!$M$3:$M$100000,"Pass") | E12: =COUNTIF('Sales – Order to Cash'!$M$3:$M$100000,"Fail") | F12: =COUNTIF('Sales – Order to Cash'!$M$3:$M$100000,"Blocked") | G12: =COUNTIF('Sales – Order to Cash'!$M$3:$M$100000,"N/A") | H12: =IFERROR(D12/(D12+E12),"")
A13: Sales – Pricing | B13: 18 | C13: =COUNTIF('Sales – Pricing'!$M$3:$M$100000,"Not Run") | D13: =COUNTIF('Sales – Pricing'!$M$3:$M$100000,"Pass") | E13: =COUNTIF('Sales – Pricing'!$M$3:$M$100000,"Fail") | F13: =COUNTIF('Sales – Pricing'!$M$3:$M$100000,"Blocked") | G13: =COUNTIF('Sales – Pricing'!$M$3:$M$100000,"N/A") | H13: =IFERROR(D13/(D13+E13),"")
A14: POS | B14: 23 | C14: =COUNTIF('POS'!$M$3:$M$100000,"Not Run") | D14: =COUNTIF('POS'!$M$3:$M$100000,"Pass") | E14: =COUNTIF('POS'!$M$3:$M$100000,"Fail") | F14: =COUNTIF('POS'!$M$3:$M$100000,"Blocked") | G14: =COUNTIF('POS'!$M$3:$M$100000,"N/A") | H14: =IFERROR(D14/(D14+E14),"")
A15: Procurement (P2P) | B15: 41 | C15: =COUNTIF('Procurement (P2P)'!$M$3:$M$100000,"Not Run") | D15: =COUNTIF('Procurement (P2P)'!$M$3:$M$100000,"Pass") | E15: =COUNTIF('Procurement (P2P)'!$M$3:$M$100000,"Fail") | F15: =COUNTIF('Procurement (P2P)'!$M$3:$M$100000,"Blocked") | G15: =COUNTIF('Procurement (P2P)'!$M$3:$M$100000,"N/A") | H15: =IFERROR(D15/(D15+E15),"")
A16: Inventory | B16: 40 | C16: =COUNTIF('Inventory'!$M$3:$M$100000,"Not Run") | D16: =COUNTIF('Inventory'!$M$3:$M$100000,"Pass") | E16: =COUNTIF('Inventory'!$M$3:$M$100000,"Fail") | F16: =COUNTIF('Inventory'!$M$3:$M$100000,"Blocked") | G16: =COUNTIF('Inventory'!$M$3:$M$100000,"N/A") | H16: =IFERROR(D16/(D16+E16),"")
A17: Manufacturing | B17: 38 | C17: =COUNTIF('Manufacturing'!$M$3:$M$100000,"Not Run") | D17: =COUNTIF('Manufacturing'!$M$3:$M$100000,"Pass") | E17: =COUNTIF('Manufacturing'!$M$3:$M$100000,"Fail") | F17: =COUNTIF('Manufacturing'!$M$3:$M$100000,"Blocked") | G17: =COUNTIF('Manufacturing'!$M$3:$M$100000,"N/A") | H17: =IFERROR(D17/(D17+E17),"")
A18: General Ledger | B18: 35 | C18: =COUNTIF('General Ledger'!$M$3:$M$100000,"Not Run") | D18: =COUNTIF('General Ledger'!$M$3:$M$100000,"Pass") | E18: =COUNTIF('General Ledger'!$M$3:$M$100000,"Fail") | F18: =COUNTIF('General Ledger'!$M$3:$M$100000,"Blocked") | G18: =COUNTIF('General Ledger'!$M$3:$M$100000,"N/A") | H18: =IFERROR(D18/(D18+E18),"")
A19: Accounts Receivable | B19: 23 | C19: =COUNTIF('Accounts Receivable'!$M$3:$M$100000,"Not Run") | D19: =COUNTIF('Accounts Receivable'!$M$3:$M$100000,"Pass") | E19: =COUNTIF('Accounts Receivable'!$M$3:$M$100000,"Fail") | F19: =COUNTIF('Accounts Receivable'!$M$3:$M$100000,"Blocked") | G19: =COUNTIF('Accounts Receivable'!$M$3:$M$100000,"N/A") | H19: =IFERROR(D19/(D19+E19),"")
A20: Accounts Payable | B20: 20 | C20: =COUNTIF('Accounts Payable'!$M$3:$M$100000,"Not Run") | D20: =COUNTIF('Accounts Payable'!$M$3:$M$100000,"Pass") | E20: =COUNTIF('Accounts Payable'!$M$3:$M$100000,"Fail") | F20: =COUNTIF('Accounts Payable'!$M$3:$M$100000,"Blocked") | G20: =COUNTIF('Accounts Payable'!$M$3:$M$100000,"N/A") | H20: =IFERROR(D20/(D20+E20),"")
A21: Cash & Bank | B21: 27 | C21: =COUNTIF('Cash & Bank'!$M$3:$M$100000,"Not Run") | D21: =COUNTIF('Cash & Bank'!$M$3:$M$100000,"Pass") | E21: =COUNTIF('Cash & Bank'!$M$3:$M$100000,"Fail") | F21: =COUNTIF('Cash & Bank'!$M$3:$M$100000,"Blocked") | G21: =COUNTIF('Cash & Bank'!$M$3:$M$100000,"N/A") | H21: =IFERROR(D21/(D21+E21),"")
A22: Tax (VAT/WHT) | B22: 29 | C22: =COUNTIF('Tax (VAT-WHT)'!$M$3:$M$100000,"Not Run") | D22: =COUNTIF('Tax (VAT-WHT)'!$M$3:$M$100000,"Pass") | E22: =COUNTIF('Tax (VAT-WHT)'!$M$3:$M$100000,"Fail") | F22: =COUNTIF('Tax (VAT-WHT)'!$M$3:$M$100000,"Blocked") | G22: =COUNTIF('Tax (VAT-WHT)'!$M$3:$M$100000,"N/A") | H22: =IFERROR(D22/(D22+E22),"")
A23: FX & Multicurrency | B23: 19 | C23: =COUNTIF('FX & Multicurrency'!$M$3:$M$100000,"Not Run") | D23: =COUNTIF('FX & Multicurrency'!$M$3:$M$100000,"Pass") | E23: =COUNTIF('FX & Multicurrency'!$M$3:$M$100000,"Fail") | F23: =COUNTIF('FX & Multicurrency'!$M$3:$M$100000,"Blocked") | G23: =COUNTIF('FX & Multicurrency'!$M$3:$M$100000,"N/A") | H23: =IFERROR(D23/(D23+E23),"")
A24: Reporting & BI | B24: 23 | C24: =COUNTIF('Reporting & BI'!$M$3:$M$100000,"Not Run") | D24: =COUNTIF('Reporting & BI'!$M$3:$M$100000,"Pass") | E24: =COUNTIF('Reporting & BI'!$M$3:$M$100000,"Fail") | F24: =COUNTIF('Reporting & BI'!$M$3:$M$100000,"Blocked") | G24: =COUNTIF('Reporting & BI'!$M$3:$M$100000,"N/A") | H24: =IFERROR(D24/(D24+E24),"")
A25: Fixed Assets | B25: 20 | C25: =COUNTIF('Fixed Assets'!$M$3:$M$100000,"Not Run") | D25: =COUNTIF('Fixed Assets'!$M$3:$M$100000,"Pass") | E25: =COUNTIF('Fixed Assets'!$M$3:$M$100000,"Fail") | F25: =COUNTIF('Fixed Assets'!$M$3:$M$100000,"Blocked") | G25: =COUNTIF('Fixed Assets'!$M$3:$M$100000,"N/A") | H25: =IFERROR(D25/(D25+E25),"")
A26: Budgeting | B26: 21 | C26: =COUNTIF('Budgeting'!$M$3:$M$100000,"Not Run") | D26: =COUNTIF('Budgeting'!$M$3:$M$100000,"Pass") | E26: =COUNTIF('Budgeting'!$M$3:$M$100000,"Fail") | F26: =COUNTIF('Budgeting'!$M$3:$M$100000,"Blocked") | G26: =COUNTIF('Budgeting'!$M$3:$M$100000,"N/A") | H26: =IFERROR(D26/(D26+E26),"")
A27: HR & Payroll | B27: 37 | C27: =COUNTIF('HR & Payroll'!$M$3:$M$100000,"Not Run") | D27: =COUNTIF('HR & Payroll'!$M$3:$M$100000,"Pass") | E27: =COUNTIF('HR & Payroll'!$M$3:$M$100000,"Fail") | F27: =COUNTIF('HR & Payroll'!$M$3:$M$100000,"Blocked") | G27: =COUNTIF('HR & Payroll'!$M$3:$M$100000,"N/A") | H27: =IFERROR(D27/(D27+E27),"")
A28: CRM | B28: 30 | C28: =COUNTIF('CRM'!$M$3:$M$100000,"Not Run") | D28: =COUNTIF('CRM'!$M$3:$M$100000,"Pass") | E28: =COUNTIF('CRM'!$M$3:$M$100000,"Fail") | F28: =COUNTIF('CRM'!$M$3:$M$100000,"Blocked") | G28: =COUNTIF('CRM'!$M$3:$M$100000,"N/A") | H28: =IFERROR(D28/(D28+E28),"")
A29: Projects | B29: 26 | C29: =COUNTIF('Projects'!$M$3:$M$100000,"Not Run") | D29: =COUNTIF('Projects'!$M$3:$M$100000,"Pass") | E29: =COUNTIF('Projects'!$M$3:$M$100000,"Fail") | F29: =COUNTIF('Projects'!$M$3:$M$100000,"Blocked") | G29: =COUNTIF('Projects'!$M$3:$M$100000,"N/A") | H29: =IFERROR(D29/(D29+E29),"")
A30: TOTAL | B30: =SUM(B3:B29) | C30: =SUM(C3:C29) | D30: =SUM(D3:D29) | E30: =SUM(E3:E29) | F30: =SUM(F3:F29) | G30: =SUM(G3:G29) | H30: =IFERROR(D30/(D30+E30),"")

Sheet IAM & Access
A1: IAM & Access — UAT
A2: ID | B2: Area | C2: Test Scenario | D2: Type | E2: Priority | F2: Preconditions | G2: Steps | H2: Test Data | I2: Expected Result | J2: Route | K2: Permission | L2: Actual Result | M2: Status | N2: Severity | O2: Tester | P2: Run Date | Q2: Comments
A3: IAM-001 | B3: Authentication | C3: Successful login lands in admin shell with correct user and branch displayed | D3: Positive | E3: High | F3: App running. rootadmin user exists with known password. At least one active company and branch exist. | G3: 1. Navigate to /login. 2. Enter username 'rootadmin' and its known password. 3. Click Sign In. 4. Wait for the admin shell to load. | H3: username: rootadmin, password: RootPass12345 | I3: Redirect to /admin. Topbar shows the user's display name or initials. The active branch name appears in the branch selector. No raw uid is shown anywhere on screen. | J3: /login | M3: Not Run
A4: IAM-002 | B4: Authentication | C4: Login with wrong password returns generic error — no user enumeration | D4: Negative | E4: High | F4: Known existing username (e.g. org.admin). | G4: 1. Navigate to /login. 2. Enter username 'org.admin' and password 'totally-wrong-1'. 3. Click Sign In. | H4: username: org.admin, password: totally-wrong-1 | I4: Stays on /login. Inline error message appears (generic 'Sign-in failed' or similar). No red modal dialog. POST /api/v1/auth/login returns 401. Error text is identical to the unknown-username case (IAM-003) — no user enumeration. | J4: /login | M4: Not Run
A5: IAM-003 | B5: Authentication | C5: Login with unknown username returns the same generic error as wrong password | D5: Negative | E5: High | F5: None. | G5: 1. Navigate to /login. 2. Enter username 'does.not.exist' and password 'Whatever123'. 3. Click Sign In. 4. Compare the error text to IAM-002's error text. | H5: username: does.not.exist, password: Whatever123 | I5: Stays on /login. Error text is word-for-word identical to the wrong-password error. 401 returned. No timing difference observable. No indication whether the username exists. | J5: /login | M5: Not Run
A6: IAM-004 | B6: Authentication | C6: Account lockout after 5 consecutive failed attempts; locked message appears | D6: Edge | E6: High | F6: A dedicated non-root test user (e.g. lockme.user) exists with a known correct password. | G6: 1. Navigate to /login. 2. Submit wrong password 5 times for 'lockme.user'. 3. On the 6th attempt submit the CORRECT password. | H6: username: lockme.user, wrong password: bad-pass-1 (×5), correct password: known value | I6: Attempts 1–4 return generic invalid-credentials message. Attempt 5 (threshold) and attempt 6 with correct password both return a distinct 'Account is locked. Try again later or contact an administrator.' message. Login is refused even with correct credentials while locked. | J6: /login | M6: Not Run
A7: IAM-005 | B7: Authentication | C7: Disabled (INACTIVE) user cannot log in | D7: Negative | E7: High | F7: A user disabled via IAM-021 (status INACTIVE). Correct password is known. | G7: 1. Navigate to /login. 2. Enter the disabled user's username and correct password. 3. Click Sign In. | H7: username: disabled.user, correct password | I7: Stays on /login. Generic invalid-credentials error shown. 401 returned. Reason for refusal not disclosed. | J7: /login | M7: Not Run
A8: IAM-006 | B8: Authentication | C8: Token refresh rotates the refresh token (single-use); reuse triggers chain revocation | D8: Edge | E8: Medium | F8: A valid login session. Capture the refreshToken R1 from the login response. | G8: 1. POST /api/v1/auth/refresh with R1 — capture new tokens (access2, R2). 2. POST /api/v1/auth/refresh again with R1 (the already-used token). 3. POST /api/v1/auth/refresh with R2 (the valid new one). | H8: R1: captured refresh token from login | I8: Step 1: 200, new access and refresh tokens returned. Step 2: 401 'Refresh token already used. Please sign in again.' (chain revoked). Step 3: also 401 — the whole chain is revoked upon reuse detection. | M8: Not Run
A9: IAM-007 | B9: Authentication | C9: Logout revokes the refresh token and clears the session | D9: Positive | E9: Medium | F9: An active logged-in session. | G9: 1. Log in as any user. 2. Open the user menu in the topbar; click Logout. 3. Attempt to navigate to /admin. 4. After logout, replay the revoked refresh token via POST /api/v1/auth/refresh. | H9: Any active user | I9: POST /api/v1/auth/logout returns 204. Browser redirects to /login. Navigating to /admin again redirects back to /login. Replaying the revoked refresh token returns 401. | J9: /admin | M9: Not Run
A10: IAM-008 | B10: Authentication | C10: Expired/invalid access token triggers session-expired toast and redirect to login | D10: Negative | E10: Medium | F10: A logged-in session. | G10: 1. Log in. 2. Corrupt or manually expire the stored access token (tamper localStorage). 3. Navigate to /admin/users to trigger an API call. | H10: Tampered access token | I10: The API returns 401. The auth error interceptor clears the session, shows a toast 'Your session has expired. Please sign in again.', and redirects to /login. No infinite redirect loop. | J10: /admin/users | M10: Not Run
A11: IAM-009 | B11: Authentication | C11: Login client-side guard: blank username/password prevents form submission | D11: Negative | E11: Medium | F11: None. | G11: 1. Navigate to /login. 2. Leave both username and password blank. 3. Click Sign In. | H11: No input | I11: Inline validation error appears ('Enter your username and password.' or similar). No POST /api/v1/auth/login is issued. Whitespace-only username is treated as empty. | J11: /login | M11: Not Run
A12: IAM-010 | B12: Authentication | C12: GET /auth/me drives permission-aware navigation (items hidden for missing permissions) | D12: Positive | E12: High | F12: Three users: NO-PERMISSION user (no roles), a CUSTOM-role user (COMPANY.VIEW + USER.VIEW only), ORG_ADMIN. | G12: 1. Log in as the NO-PERMISSION user; inspect the sidebar items. 2. Log out; log in as the CUSTOM-role user; inspect the sidebar. 3. Log out; log in as ORG_ADMIN; inspect the sidebar. | H12: Users: qa.noperm, qa.custom (COMPANY.VIEW+USER.VIEW), qa.orgadmin | I12: NO-PERMISSION: no permission-gated nav items visible. CUSTOM: only Companies and Users nav items appear. ORG_ADMIN: all Administration items visible. GET /api/v1/auth/me returns the corresponding permissions[] array for each. | J12: /admin | M12: Not Run
A13: IAM-011 | B13: Authentication | C13: GET /auth/my-branches lists only ACTIVE switchable branches for the user | D13: Positive | E13: Medium | F13: A user assigned to at least 2 ACTIVE branches and 1 ARCHIVED/inactive branch. | G13: 1. Log in as that user. 2. Open the topbar branch selector. | H13: User with branches: HQ (ACTIVE), Mwanza (ACTIVE), Old Branch (ARCHIVED) | I13: Only the two ACTIVE branches appear in the selector. The archived branch is not listed. Branches are shown by name, not by uid. The current active branch is highlighted. | J13: /admin | M13: Not Run
A14: IAM-012 | B14: Authentication | C14: Branch switch re-resolves permissions and sends X-Branch-Uid header | D14: Positive | E14: High | F14: A user assigned to Branch A (default) and Branch B, with different effective grants per branch. | G14: 1. Log in (lands on Branch A). Note the nav items. 2. Open the branch selector; pick Branch B by name. 3. Observe the nav items and confirm subsequent API calls carry X-Branch-Uid: <B-uid>. | H14: Branch A: HQ (default), Branch B: Mwanza Depot | I14: After switching to Branch B, GET /api/v1/auth/me is called with X-Branch-Uid header set to Branch B's uid. Nav recomputes to reflect Branch B's effective permissions. No re-login required. Branch is selected by name — uid only goes in the header. | J14: /admin | M14: Not Run
A15: IAM-013 | B15: Users | C15: Create a user with valid data | D15: Positive | E15: High | F15: Logged in as ORG_ADMIN (holds USER.MANAGE). | G15: 1. Navigate to /admin/users. 2. Fill the create form: username, display name, password. 3. Submit. | H15: username: new.clerk, displayName: New Clerk, password: Welcome123 | I15: POST /api/v1/users returns 201. New row appears in the table showing username and display name (no uid visible). Toast 'User created'. is_root is false. User status is ACTIVE. | J15: /admin/users | K15: USER.MANAGE | M15: Not Run
A16: IAM-014 | B16: Users | C16: Create user: duplicate username rejected (case-insensitive) | D16: Negative | E16: High | F16: Logged in as ORG_ADMIN. Existing username 'org.admin' is present. | G16: 1. Navigate to /admin/users. 2. Submit create form with username 'ORG.ADMIN' (different case). | H16: username: ORG.ADMIN (duplicate of org.admin) | I16: 409 returned. Inline form error 'Username already exists: org.admin'. No new row added. | J16: /admin/users | K16: USER.MANAGE | M16: Not Run
A17: IAM-015 | B17: Users | C17: Create user: password too short (< 8 chars) rejected | D17: Negative | E17: High | F17: Logged in as ORG_ADMIN. | G17: 1. Navigate to /admin/users. 2. Submit create form with password 'Ab1' (3 chars). | H17: password: Ab1 | I17: 400 or 409 with error 'Password must be at least 8 characters.' Inline error shown. User not created. Boundary: exactly 8 chars passes; 7 chars fails. | J17: /admin/users | K17: USER.MANAGE | M17: Not Run
A18: IAM-016 | B18: Users | C18: Create user: common password rejected; no-letter and no-digit passwords rejected | D18: Negative | E18: High | F18: Logged in as ORG_ADMIN. | G18: 1. Attempt (a) password 'abcdefgh' (no digit). 2. Attempt (b) password 'password1' (common list). 3. Attempt (c) password '12345678' (no letter + common). 4. Attempt (d) password 'Welcome123' (valid). | H18: passwords: abcdefgh, password1, 12345678, Welcome123 | I18: (a) 'Password must contain letters and at least one number.' (b) 'Password is too common; choose a stronger one.' (c) rejected (no letter and common). (d) user created successfully. Each common-list entry (password, password1, 12345678, qwerty123, admin123, letmein123, changeme, welcome1, passw0rd) is rejected. | J18: /admin/users | K18: USER.MANAGE | M18: Not Run
A19: IAM-017 | B19: Users | C19: Disable an active user (status → INACTIVE) | D19: Positive | E19: High | F19: Logged in as ORG_ADMIN. An ACTIVE non-root user exists. | G19: 1. Navigate to /admin/users. 2. On the target row, click Disable. 3. Reload the page. | H19: Target user: new.clerk (ACTIVE) | I19: PUT /api/v1/users/uid/{uid}/disable returns 204. On reload GET /api/v1/users shows the user with status 'INACTIVE'. Disable action is NOT rendered for root users. | J19: /admin/users | K19: USER.MANAGE | M19: Not Run
A20: IAM-018 | B20: Users | C20: Enable a disabled user (status → ACTIVE); re-login then succeeds | D20: Positive | E20: Medium | F20: An INACTIVE user (from IAM-017). | G20: 1. Navigate to /admin/users. 2. On the disabled row, click Enable. 3. Log out; log in as the re-enabled user. | H20: Target user: new.clerk (INACTIVE) | I20: PUT /api/v1/users/uid/{uid}/enable returns 204. Status returns to ACTIVE on reload. The user can log in again. | J20: /admin/users | K20: USER.MANAGE | M20: Not Run
A21: IAM-019 | B21: Users | C21: Admin unlock clears lockout; login then succeeds | D21: Positive | E21: Medium | F21: A locked user (from IAM-004). | G21: 1. Log in as ORG_ADMIN; navigate to /admin/users. 2. Locate the locked user; click Unlock. 3. Log out; log in as the unlocked user with the correct password. | H21: Locked user: lockme.user | I21: PUT /api/v1/users/uid/{uid}/unlock returns 204. User row no longer shows locked status. Subsequent login with correct password succeeds. | J21: /admin/users | K21: USER.MANAGE | M21: Not Run
A22: IAM-020 | B22: Users | C22: Admin password reset; user can log in with new password | D22: Positive | E22: High | F22: Logged in as ORG_ADMIN. A non-root user exists. | G22: 1. Navigate to /admin/users. 2. Expand the set-password form for the target user. 3. Enter a policy-valid password; save. 4. Log out; log in as that user with the new password. | H22: New password: Reset2026 | I22: PUT /api/v1/users/uid/{uid}/password returns 204. Toast 'Password updated'. Password never appears in a log or audit detail. Login with the new password succeeds. | J22: /admin/users | K22: USER.MANAGE | M22: Not Run
A23: IAM-021 | B23: Users | C23: Viewer-only user (USER.VIEW, no USER.MANAGE) cannot perform management actions | D23: Permission | E23: High | F23: A user holding USER.VIEW but NOT USER.MANAGE. | G23: 1. Log in as the view-only user. 2. Navigate to /admin/users (list loads). 3. Attempt to click Disable, Unlock, or the set-password form. 4. Force POST /api/v1/users directly. | H23: User: qa.viewer (USER.VIEW only) | I23: List renders. Management actions (Disable, Enable, Unlock, Set Password, Create) are hidden. Forced POST returns 403. No red modal — 403 is handled as a calm state. | J23: /admin/users | K23: USER.VIEW | M23: Not Run
A24: IAM-022 | B24: Users | C24: No-permission user cannot reach /admin/users; route guard redirects to /admin/home | D24: Permission | E24: High | F24: A user with no roles/permissions (qa.noperm). | G24: 1. Log in as qa.noperm. 2. Navigate directly to /admin/users. | H24: User: qa.noperm | I24: Route guard redirects to /admin/home. The Users nav item is absent from the sidebar. GET /api/v1/users returns 403. | J24: /admin/users | M24: Not Run
A25: IAM-023 | B25: Users | C25: User detail: uid only in URL, never displayed; branch/role panels use name pickers | D25: Positive | E25: High | F25: Logged in as ORG_ADMIN. A user exists. | G25: 1. From /admin/users, click the row action to open /admin/users/uid/:uid. 2. Inspect the page header, branch-assignment panel, and role-grant panel. 3. Scan all visible text for uid strings. | H25: Any existing user | I25: Header shows username/display name/status — no uid text. The uid appears only in the URL path. Branch and role pickers select by name from dropdowns. No raw uid is typed or shown in any label or cell. | J25: /admin/users/uid/:uid | K25: USER.VIEW | M25: Not Run
A26: IAM-024 | B26: Roles | C26: Create a role with org-unique code | D26: Positive | E26: High | F26: Logged in as ORG_ADMIN (holds ROLE.MANAGE). | G26: 1. Navigate to /admin/roles. 2. Fill create form: code, name, optional description. 3. Submit. | H26: code: BRANCH_SUP, name: Branch Supervisor, description: Reviews branch ops | I26: POST /api/v1/roles returns 201. New row appears. Role is non-system (system: false), status ACTIVE, empty permissionCodes. Row links to /admin/roles/uid/:uid — uid only in URL. | J26: /admin/roles | K26: ROLE.MANAGE | M26: Not Run
A27: IAM-025 | B27: Roles | C27: Create role: duplicate code rejected | D27: Negative | E27: High | F27: Role with code BRANCH_SUP already exists. | G27: 1. Navigate to /admin/roles. 2. Submit create form with code 'BRANCH_SUP'. | H27: code: BRANCH_SUP (duplicate) | I27: 409 returned. Inline error 'Role code already exists: BRANCH_SUP'. No row added. | J27: /admin/roles | K27: ROLE.MANAGE | M27: Not Run
A28: IAM-026 | B28: Roles | C28: Set role permissions via grouped checkbox UI (replace semantics) | D28: Positive | E28: High | F28: Logged in as ORG_ADMIN (holds ROLE.MANAGE + PERMISSION.VIEW). A custom role exists. | G28: 1. Navigate to /admin/roles/uid/:uid for the custom role. 2. Check USER.VIEW and USER.MANAGE; uncheck all others. 3. Save permissions. | H28: Role: BRANCH_SUP; permissions to set: USER.VIEW, USER.MANAGE | I28: PUT /api/v1/roles/uid/{uid}/permissions returns 200 RoleDto with sorted permissionCodes [USER.MANAGE, USER.VIEW]. Checkbox state reflects the saved set. Saving an empty list is valid (clears all permissions). | J28: /admin/roles/uid/:uid | K28: ROLE.MANAGE | M28: Not Run
A29: IAM-027 | B29: Roles | C29: Archive a non-system role; system role archive blocked | D29: Positive | E29: High | F29: Logged in as ORG_ADMIN. A custom non-system role and a seeded system role (e.g. ORG_ADMIN) both exist. | G29: 1. Archive the custom role BRANCH_SUP. 2. Attempt to archive the system role ORG_ADMIN. | H29: Custom role: BRANCH_SUP, System role: ORG_ADMIN | I29: Custom role: 204, status ARCHIVED (soft-delete, row still exists). System role attempt: 409 'System role cannot be archived: ORG_ADMIN'. Cache invalidated after archive. | J29: /admin/roles | K29: ROLE.MANAGE | M29: Not Run
A30: IAM-028 | B30: Roles | C30: ROLE.VIEW-only user cannot create or edit roles; edit route redirects to home | D30: Permission | E30: High | F30: A user holding ROLE.VIEW but NOT ROLE.MANAGE. | G30: 1. Log in as the ROLE.VIEW-only user. 2. Navigate to /admin/roles (list loads). 3. Navigate directly to /admin/roles/uid/:uid (the edit screen). | H30: User: qa.roleviewer (ROLE.VIEW only) | I30: List loads. Create form/button is hidden. Direct navigation to the edit route redirects to /admin/home. PUT /api/v1/roles/uid/{uid}/permissions returns 403. | J30: /admin/roles | K30: ROLE.VIEW | M30: Not Run
A31: IAM-029 | B31: Role Assignment | C31: Grant a company-wide role to a user via pickers (no uid typed) | D31: Positive | E31: High | F31: Logged in as ORG_ADMIN (holds ROLE.MANAGE). Target user and role exist. | G31: 1. Navigate to /admin/role-grants. 2. Choose user by display name (picker), role by name, company by name; leave branch blank. 3. Click Grant. | H31: user: New Clerk, role: Branch Supervisor, company: (active company name) | I31: POST /api/v1/user-roles returns 201 UserRoleDto with branchUid: null. Toast 'Role granted'. Grant appears when the user's grants are listed. No uid typed or shown during the process. | J31: /admin/role-grants | K31: ROLE.MANAGE | M31: Not Run
A32: IAM-030 | B32: Role Assignment | C32: Grant role scoped to a specific branch (branch picker loads on company selection) | D32: Positive | E32: High | F32: Logged in as ORG_ADMIN. Multi-branch company exists. | G32: 1. Navigate to /admin/role-grants. 2. Pick user, role, company; after company selection the branch picker reloads. 3. Pick a branch by name; click Grant. | H32: user: New Clerk, role: Branch Supervisor, branch: Mwanza Depot | I32: 201 with branchUid set to the chosen branch. Grant is effective only in that branch context. Branch selected by name — uid stored under the hood. | J32: /admin/role-grants | K32: ROLE.MANAGE | M32: Not Run
A33: IAM-031 | B33: Role Assignment | C33: Duplicate active grant rejected (same user/role/company/branch combination) | D33: Negative | E33: Medium | F33: An existing active grant for a user+role+company+branch combination. | G33: 1. Navigate to /admin/role-grants. 2. Attempt to re-grant the exact same combination. | H33: Same user, role, company, branch as an existing active grant | I33: 409 'Active grant already exists for this user/role/company/branch combination.' Inline form error. No duplicate row created. | J33: /admin/role-grants | K33: ROLE.MANAGE | M33: Not Run
A34: IAM-032 | B34: Role Assignment | C34: Revoke a role grant; grantee's effective permissions drop | D34: Positive | E34: High | F34: Logged in as ORG_ADMIN. A grant exists for a target user. | G34: 1. Navigate to /admin/role-grants; look up grants for the target user. 2. On a grant row, click Revoke. 3. Have the target user call GET /api/v1/customers to verify permission loss. | H34: Target user with an active grant | I34: DELETE /api/v1/user-roles/uid/{uid} returns 204. Row removed from list on reload. Target user immediately loses the revoked permissions (cache invalidated). Their subsequent API call returns 403. | J34: /admin/role-grants | K34: ROLE.MANAGE | M34: Not Run
A35: IAM-033 | B35: Role Assignment | C35: Cross-tenant role grant denied (ScopeGuard): acting in Company A cannot grant in Company B | D35: Permission | E35: High | F35: Two companies A and B. Non-root ORG_ADMIN scoped to Company A. Company B has a grant to revoke. | G35: 1. Log in as Company A's admin (active company = A). 2. POST /api/v1/user-roles with companyUid = Company B. 3. DELETE a Company-B grant uid. | H35: companyUid: Company B's uid | I35: Both calls return 403. ScopeGuard.assertCanActIn denies cross-company action. rootadmin performing the same action succeeds and emits a ROOT.BYPASS audit row. | J35: /admin/role-grants | K35: ROLE.MANAGE | M35: Not Run
A36: IAM-034 | B36: Branch Assignment | C36: Assign a user to a branch (non-default) via the user-detail panel | D36: Positive | E36: High | F36: Logged in as ORG_ADMIN (holds BRANCH.ASSIGN). A user with no branch assignment and a company with branches exist. | G36: 1. Navigate to /admin/users/uid/:uid. 2. In the Branch panel: pick company by name, then pick branch by name; leave make-default unchecked. 3. Click Assign. | H36: Branch: HQ | I36: POST /api/v1/user-branches returns 201. Branch appears in the user's assignments by name. No uid typed or shown. | J36: /admin/users/uid/:uid | K36: BRANCH.ASSIGN | M36: Not Run
... A49: IAM-047 | B49: Companies & Branches | C49: rootadmin cannot be disabled via the API (409 safeguard) | D49: Edge | E49: High | F49: Logged in as ORG_ADMIN with USER.MANAGE. | G49: 1. Call PUT /api/v1/users/uid/{rootadmin-uid}/disable directly. | H49: rootadmin uid | I49: 409 'A root administrator cannot be disabled via the API.' No status change. The Disable action is not rendered for root users in the UI. | J49: /admin/users | K49: USER.MANAGE | M49: Not Run

Sheet RBAC
A1: RBAC — UAT
A2: ID | B2: Area | C2: Test Scenario | D2: Type | E2: Priority | F2: Preconditions | G2: Steps | H2: Test Data | I2: Expected Result | J2: Route | K2: Permission | L2: Actual Result | M2: Status | N2: Severity | O2: Tester | P2: Run Date | Q2: Comments
A3: RBAC-001 | B3: Role Bundles | C3: /auth/me returns correct effective permission set per role | D3: Positive | E3: High | F3: Operational role bundles seeded for: ORG_ADMIN, SALES_MANAGER, SALES_REP, ACCOUNTANT, STOREKEEPER, PURCHASE_OFFICER, CUSTOM (CUSTOMER.VIEW+PRODUCT.VIEW only), NO-PERM. | G3: 1. Log in as each test user in turn. 2. Call GET /api/v1/auth/me and capture permissions[]. | H3: Users: qa.orgadmin, qa.salesmgr, qa.salesrep, qa.accountant, qa.storekeeper, qa.purchaser, qa.custom, qa.noperm | I3: ORG_ADMIN: superset covering all modules. Each operational user: set equals its intended bundle. qa.noperm: permissions: []. rootadmin: isRoot: true. Any divergence from the design matrix is logged as a finding. | J3: /admin | M3: Not Run
A4: RBAC-002 | B4: Role Bundles | C4: ORG_ADMIN can administer companies, users, and roles | D4: Positive | E4: High | F4: qa.orgadmin logged in. | G4: 1. Navigate to /admin/companies, /admin/users, /admin/roles. 2. Confirm all three nav items are visible. 3. Open a create form on each. | H4: qa.orgadmin | I4: All three screens load (four states: loading → loaded). Create forms are reachable. POST on each returns 201. No uid shown in any cell or label. | J4: /admin/companies | K4: COMPANY.MANAGE | M4: Not Run
A5: RBAC-003 | B5: Role Bundles | C5: SALES_MANAGER can create/confirm sales orders; cannot access GL or IAM-admin | D5: Positive | E5: High | F5: qa.salesmgr logged in. At least one customer and product seeded. | G5: 1. Navigate to /admin/sales-orders; create an order (pick customer + product by name). 2. Confirm the order. 3. Navigate directly to /admin/gl/journals. 4. Navigate directly to /admin/users. 5. Call GET /api/v1/gl/journals and GET /api/v1/users directly. | H5: Customer: Acme Traders, product: Sugar 1kg, qty: 5 | I5: Create and Confirm succeed. /admin/gl/journals and /admin/users redirect to /admin/home. GL and Users nav items are absent. Both direct API calls return 403 with the generic message. | J5: /admin/sales-orders | K5: SALES.ORDER.CREATE | M5: Not Run
A6: RBAC-004 | B6: Role Bundles | C6: SALES_REP can create sales orders but NOT confirm or cancel them | D6: Permission | E6: High | F6: qa.salesrep logged in. A DRAFT sales order exists created by the rep. | G6: 1. Create a sales order (succeeds). 2. Look for Confirm and Cancel controls on the order detail. 3. Call PUT /api/v1/sales-orders/uid/{uid}/confirm directly. | H6: qa.salesrep; a DRAFT order | I6: Create returns 201. Confirm and Cancel buttons are NOT rendered (action-level gating). Direct confirm API returns 403. | J6: /admin/sales-orders | K6: SALES.ORDER.CREATE | M6: Not Run
A7: RBAC-005 | B7: Role Bundles | C7: ACCOUNTANT can post GL, record AR receipts, run AP payments; cannot create sales or manage users | D7: Positive | E7: High | F7: qa.accountant logged in. Open fiscal period; an AR invoice and AP bill exist. | G7: 1. Post a balanced journal (pick accounts by name). 2. Record an AR receipt. 3. Run an AP payment. 4. Navigate to /admin/sales-orders/create and /admin/users directly. 5. POST /api/v1/sales-orders directly. | H7: qa.accountant | I7: Steps 1-3 succeed. Steps 4-5: sales-create and users redirect to home / nav hidden. POST /api/v1/sales-orders returns 403. | J7: /admin/gl/journals | K7: GL.POST | M7: Not Run
A8: RBAC-006 | B8: Role Bundles | C8: STOREKEEPER can adjust stock and create/receive stock transfers; cannot access GL or sales | D8: Positive | E8: High | F8: qa.storekeeper logged in. At least one product and two stock locations exist. | G8: 1. Navigate to /admin/stock; adjust on-hand (pick product by name). 2. Navigate to /admin/stock-transfers; create a transfer (pick locations by name); receive it. 3. Navigate directly to /admin/gl/journals and /admin/sales-orders. 4. GET /api/v1/gl/journals directly. | H8: qa.storekeeper | I8: Steps 1-2 succeed. Steps 3-4: GL and sales redirect to home / nav hidden; direct API returns 403. | J8: /admin/stock | K8: STOCK.ADJUST | M8: Not Run
A9: RBAC-007 | B9: Role Bundles | C9: PURCHASE_OFFICER can create POs; cannot approve or void them | D9: Permission | E9: High | F9: qa.purchaser logged in. At least one supplier exists. | G9: 1. Create a PO (pick supplier by name). 2. Look for Approve and Void controls on the PO detail. 3. Call POST /api/v1/purchase-orders/uid/{uid}/approve directly. | H9: qa.purchaser; supplier: ABC Supplies | I9: Create returns 201. Approve and Void controls not rendered (action-level gating). Direct approve returns 403. Segregation of duties enforced by permission code, not ownership. | J9: /admin/purchase-orders | K9: PURCHASE.ORDER.CREATE | M9: Not Run
A10: RBAC-008 | B10: Role Bundles | C10: CUSTOM role (CUSTOMER.VIEW + PRODUCT.VIEW) sees only those two screens; all else hidden/403 | D10: Permission | E10: High | F10: qa.custom user assigned the CUSTOM role (exactly CUSTOMER.VIEW + PRODUCT.VIEW). | G10: 1. Log in as qa.custom. 2. Inspect the sidebar items. 3. Navigate to /admin/customers and /admin/products (load). 4. Navigate to /admin/suppliers, /admin/sales-orders, /admin/gl/journals directly. 5. POST /api/v1/customers and GET /api/v1/suppliers directly. | H10: qa.custom | I10: Sidebar shows only Customers and Products (no Create button — lacks MANAGE codes). Other routes redirect to /admin/home. POST /api/v1/customers returns 403. GET /api/v1/suppliers returns 403. | J10: /admin/customers | K10: CUSTOMER.VIEW | M10: Not Run
A11: RBAC-009 | B11: Role Bundles | C11: NO-PERM user: empty nav, every protected screen redirects, every API returns 403 | D11: Permission | E11: High | F11: qa.noperm user has no role grant. | G11: 1. Log in as qa.noperm. 2. Inspect the sidebar. 3. Navigate directly to /admin/customers, /admin/users, /admin/gl/journals. 4. Call GET /api/v1/customers and GET /api/v1/users. | H11: qa.noperm | I11: Sidebar shows no permission-gated items. Every protected route redirects to /admin/home. All protected API calls return 403 with the generic message. GET /api/v1/auth/me returns permissions: []. GET /auth/my-branches still succeeds (authentication, not authorization). | J11: /admin | M11: Not Run
A12: RBAC-010 | B12: Scope Enforcement | C12: Cross-tenant denial: ORG_ADMIN of Tenant A cannot touch Tenant B's customer | D12: Permission | E12: High | F12: Two tenants A and B, each with a customer. Company A's qa.orgadmin is granted ORG_ADMIN in Company A only. | G12: 1. Log in as Company A admin (active company = A). 2. Obtain Company B customer uid out-of-band. 3. Call PUT /api/v1/customers/uid/{B_customer_uid}. 4. Call GET /api/v1/customers/uid/{B_customer_uid}. | H12: Company B customer: Bravo Ltd | I12: Both calls return 403. ScopeGuard.canActOn detects target's company = B ≠ active A. Company B's customer never appears in Company A's list. An unresolvable uid also returns 403 (not 404 — avoids existence leak). | J12: /admin/customers | K12: CUSTOMER.MANAGE | M12: Not Run
A13: RBAC-011 | B13: Scope Enforcement | C13: @perm.scoped on body companyUid: create denied when companyUid != active company | D13: Permission | E13: High | F13: Two companies A and B. User holds SALES.ORDER.CREATE scoped to Company A. | G13: 1. Log in (active company A). 2. POST /api/v1/sales-orders with companyUid = Company B. 3. POST /api/v1/gl/journals with companyUid = Company B. | H13: companyUid: Company B's uid | I13: Both return 403 (body-scoped guard: holds perm but B != active A). Same calls with companyUid = A succeed (201), proving the gate is scope not the permission itself. | J13: /admin/sales-orders | K13: SALES.ORDER.CREATE | M13: Not Run
A14: RBAC-012 | B14: Scope Enforcement | C14: Branch-scoped grant: user with role only in Branch 1 is denied STOCK.VIEW in Branch 2 | D14: Permission | E14: High | F14: Company A with branch1 (default) and branch2. User granted STOCK.VIEW/STOCK.ADJUST scoped to branch1 only. | G14: 1. Log in (default branch1). View stock → 200. 2. Switch active branch to branch2 (branch selector by name). 3. Call GET /api/v1/stock. | H14: branch1, branch2; STOCK.VIEW grant on branch1 only | I14: branch1: stock loads. After switching to branch2: GET /api/v1/stock returns 403 (no grant in branch2). Nav reflects loss of STOCK.VIEW. Switch back to branch1 restores access — all without re-login. | J14: /admin/stock | K14: STOCK.VIEW | M14: Not Run
A15: RBAC-013 | B15: Scope Enforcement | C15: Company-wide grant (branch_id NULL) works in all branches of the same company | D15: Positive | E15: Medium | F15: Company A with branch1 and branch2. User has STOCK.VIEW granted with branch_id = NULL (all branches). | G15: 1. Log in (branch1). View stock → 200. 2. Switch to branch2. View stock → expect 200. | H15: NULL-branch grant | I15: Stock loads in both branches (NULL branch_id = effective company-wide). Data differs per branch (branch-scoped rows) but the permission holds in both. Switching to a different company branch fails (cross-tenant). | J15: /admin/stock | K15: STOCK.VIEW | M15: Not Run
A16: RBAC-014 | B16: Scope Enforcement | C16: Acting in an unassigned branch via forged X-Branch-Uid is denied | D16: Permission | E16: High | F16: User assigned (UserBranch) to branch1 only. Branch2 exists in the same company. | G16: 1. Log in. 2. Confirm branch2 is NOT in the branch selector (only branch1 listed). 3. Send an API call with X-Branch-Uid: branch2. | H16: branch2 uid (not assigned) | I16: Branch selector shows only branch1. Forged override to branch2 is rejected by the filter (no effective scope there) → 403. The UI cannot reach branch2 at all for this user. | J16: /admin | M16: Not Run
A17: RBAC-015 | B17: Scope Enforcement | C17: Effective permissions update promptly after grant/revoke (cache invalidated) | D17: Edge | E17: Medium | F17: ORG_ADMIN and a target user holding a role with CUSTOMER.VIEW. | G17: 1. As ORG_ADMIN, revoke the target's role (DELETE /api/v1/user-roles/uid/{uid}). 2. Immediately, as the target, call GET /api/v1/customers. 3. Re-grant and retry. | H17: Target user; role with CUSTOMER.VIEW | I17: After revoke: GET /api/v1/customers returns 403 promptly (cache invalidated by invalidate()). After re-grant: 200 returned. GET /api/v1/auth/me reflects the change in the permissions array. | J17: /admin/customers | K17: CUSTOMER.VIEW | M17: Not Run
A18: RBAC-016 | B18: Security Contract | C18: 401 vs 403 response contract; error message never names the required permission | D18: Negative | E18: Medium | F18: A protected endpoint accessible by ORG_ADMIN. | G18: 1. Call the endpoint with no bearer token. 2. Call the same endpoint with a valid token from qa.noperm (insufficient permission). | H18: No token; qa.noperm token | I18: Step 1: 401, body ApiResponse.error('Authentication is required.'). Step 2: 403, body ApiResponse.error('You do not have permission to perform this action.'). Neither message names the required permission code, the resource, or whether it exists. | J18: /api/v1/customers | M18: Not Run
A19: RBAC-017 | B19: Security Contract | C19: Nav-hidden / route-guarded / API-gated are consistent for the same permission code | D19: Positive | E19: High | F19: A user lacking COMPANY.VIEW. | G19: 1. Confirm the Companies nav item is absent from the sidebar. 2. Navigate directly to /admin/companies — confirm redirect to /admin/home. 3. Call GET /api/v1/companies — confirm 403. | H19: User lacking COMPANY.VIEW | I19: All three enforcement points (nav, route guard, API) agree: no Companies access. The same test repeated for STOCK.VIEW (stock), SALES.ORDER.VIEW (sales-orders), GL.VIEW (gl/journals), PURCHASE.ORDER.VIEW (purchase-orders). Any mismatch is a finding. | J19: /admin/companies | K19: COMPANY.VIEW | M19: Not Run
A20: RBAC-018 | B20: Security Contract | C20: POS session/sale/till: non-root users (including ORG_ADMIN) receive 403 — known defect | D20: Negative | E20: High | F20: qa.orgadmin (holds SALES.POS.* codes from V43 seed). A POS till exists. | G20: 1. Log in as qa.orgadmin. 2. Navigate to /admin/pos/sessions; attempt to open a session. 3. Navigate to /admin/pos/sell; attempt to ring a sale. 4. Navigate to /admin/pos/tills; attempt to list/create. 5. Call POST /api/v1/pos/sessions, POST /api/v1/pos/sales, GET /api/v1/pos/tills directly. | H20: qa.orgadmin | I20: EXPECTED FAILURE (known defect): All non-root users get 403 on POS endpoints. Controllers require POS.SESSION.*/POS.SALE.CREATE/POS.TILL.* codes; the seeded catalogue defines SALES.POS.* codes — these do not match. POS nav items are hidden for non-root. Only rootadmin (bypass) can operate POS. Record the defect; do not mark as a pass. | J20: /admin/pos/sessions | K20: POS.SESSION.OPEN | M20: Not Run
A21: RBAC-019 | B21: Security Contract | C21: GL.YEAR.CLOSE restricted to ORG_ADMIN; ACCOUNTANT is denied | D21: Permission | E21: Medium | F21: qa.orgadmin and qa.accountant. A fiscal year eligible to close exists. | G21: 1. As ORG_ADMIN: open the year-end close screen; run the close. 2. As ACCOUNTANT: navigate to the year-end close route; attempt the same via API. | H21: qa.orgadmin, qa.accountant | I21: ORG_ADMIN: close succeeds. ACCOUNTANT: nav hidden, route redirects to home, API returns 403. Closing an already-closed year returns a business 4xx (distinct from 403). | J21: /admin/gl/periods/fiscal-years | K21: GL.YEAR.CLOSE | M21: Not Run
A22: RBAC-020 | B22: Security Contract | C22: NOTIFICATION.ADMIN restricted to ORG_ADMIN; all operational roles get NOTIFICATION.VIEW | D22: Permission | E22: Medium | F22: qa.salesmgr (holds NOTIFICATION.VIEW) and qa.orgadmin (holds NOTIFICATION.ADMIN). | G22: 1. As qa.salesmgr: view notifications and manage own preferences (succeed). Attempt the admin type-catalogue endpoint. 2. As qa.orgadmin: open the admin type catalogue (succeeds). | H22: qa.salesmgr, qa.orgadmin | I22: Operational user: view/preferences OK; admin catalogue endpoint returns 403. ORG_ADMIN: all notifications endpoints succeed. qa.noperm: even NOTIFICATION.VIEW returns 403. | J22: /admin/notifications | K22: NOTIFICATION.ADMIN | M22: Not Run

Sheet Platform – Documents
A1: Platform – Documents — UAT
A2: ID | B2: Area | C2: Test Scenario | D2: Type | E2: Priority | F2: Preconditions | G2: Steps | H2: Test Data | I2: Expected Result | J2: Route | K2: Permission | L2: Actual Result | M2: Status | N2: Severity | O2: Tester | P2: Run Date | Q2: Comments
A3: PLAT-001 | B3: Document Log | C3: Generated documents log lists for the active company | D3: Positive | E3: High | F3: Logged in as ORG_ADMIN (holds DOCUMENT.VIEW). At least one rendered document exists for the company. | G3: 1. Navigate to /admin/documents. 2. Observe the list loads with columns: document number, type badge, source reference, generated-at, download action. | H3: company: Acme Co (default) | I3: GET /api/v1/documents returns 200 ApiResponse<List> + meta (page, size, totalElements, totalPages, hasNext). Table renders rows. No raw uid shown in any column. Paginator present and self-hides when only one page. | J3: /admin/documents | K3: DOCUMENT.VIEW | M3: Not Run
A4: PLAT-002 | B4: Document Log | C4: Documents log: four screen states (loading / empty / error / forbidden) | D4: Edge | E4: Medium | F4: ORG_ADMIN for normal states; NO-PERMISSION user for forbidden state. | G4: 1. Throttle the list response to observe the loading spinner. 2. Switch to a company with no documents to observe the empty state. 3. Force a network error to observe the error state. 4. Log in as NO-PERMISSION user and navigate to /admin/documents. | H4: Empty company; simulated 500; qa.noperm | I4: Each state is visually distinct: loading spinner, explicit 'no documents' message, error panel with retry, forbidden message. Never a silent blank page. NO-PERMISSION: Documents nav group hidden; 403 on direct API call. | J4: /admin/documents | K4: DOCUMENT.VIEW | M4: Not Run
A5: PLAT-003 | B5: Document Log | C5: Filter documents log by DocumentType | D5: Positive | E5: Medium | F5: Logged in as ORG_ADMIN. Documents of mixed types exist. | G5: 1. On /admin/documents choose 'Invoice' in the Type filter. 2. Assert only INVOICE rows show. 3. Switch to 'AR Statement' → only AR_STATEMENT rows. 4. Switch to 'All types' → full list. | H5: Types: INVOICE, AR_STATEMENT | I5: Server-side filter applied (request carries type=INVOICE). Page resets to 0 on filter change. Badge per type. Reserved types (PAYSLIP, QUOTATION, DEBIT_NOTE) are not offered in the filter select. Filter with no matches → empty state. | J5: /admin/documents | K5: DOCUMENT.VIEW | M5: Not Run
A6: PLAT-004 | B6: Document Render | C6: Render an INVOICE document — source chosen via picker by invoice number | D6: Positive | E6: High | F6: Logged in as ORG_ADMIN (holds DOCUMENT.RENDER). A finalised sales invoice exists. | G6: 1. On /admin/documents, click 'Render document'; choose Type = Invoice. 2. In the source picker select the invoice BY its invoice number (not uid). 3. Submit; observe toast and new log row. | H6: Invoice number: INV-2026-0007 | I6: POST /api/v1/documents/render returns 200 GeneratedDocumentDto with downloadUrl. New row appears at top of log showing INVOICE badge. No uid typed or shown during the process. DOCUMENT.VIEW-only user cannot see the render button. | J6: /admin/documents | K6: DOCUMENT.RENDER | M6: Not Run
A7: PLAT-005 | B7: Document Render | C7: Render each renderable DocumentType: PURCHASE_ORDER, GOODS_RECEIPT, DELIVERY_NOTE, CREDIT_NOTE | D7: Positive | E7: High | F7: Logged in as ORG_ADMIN. Source records exist for each type. | G7: For each type (PURCHASE_ORDER, GOODS_RECEIPT, DELIVERY_NOTE, CREDIT_NOTE): 1. Open render form. 2. Select type; pick source by its human number. 3. Submit. | H7: PO-0003, GRN-0002, DEL-0005, RET-0001 | I7: Each render succeeds (200). Correct documentType badge on the new row. Correct source linkage. Source picker for each type shows only records of that type. | J7: /admin/documents | K7: DOCUMENT.RENDER | M7: Not Run
A8: PLAT-006 | B8: Document Render | C8: Render an AR_STATEMENT with JSON sourceParams (customer chosen by name) | D8: Positive | E8: Medium | F8: Logged in as ACCOUNTANT (holds DOCUMENT.RENDER). A customer with open AR items exists. | G8: 1. Open render form; choose Type = AR Statement. 2. The form switches to JSON params input; enter customer (chosen by name via picker) and date range. 3. Submit. | H8: customer: (picked by name), fromDate: 2026-01-01, toDate: 2026-06-30 | I8: Statement renders; row shows AR_STATEMENT badge; 200 returned. AR_STATEMENT submitted with empty params returns inline validation error. Non-statement type with no source uid also fails inline. | J8: /admin/documents | K8: DOCUMENT.RENDER | M8: Not Run
A9: PLAT-007 | B9: Document Render | C9: Render a reserved DocumentType (PAYSLIP) is rejected by the server | D9: Negative | E9: Low | F9: Logged in as ORG_ADMIN. | G9: 1. Call POST /api/v1/documents/render with documentType=PAYSLIP (not selectable in UI). | H9: documentType: PAYSLIP | I9: Request rejected with error envelope (4xx). No log row created. The UI does not offer PAYSLIP/QUOTATION/DEBIT_NOTE in the type select — server enforcement is the backstop. | J9: /admin/documents | K9: DOCUMENT.RENDER | M9: Not Run
A10: PLAT-008 | B10: Document Render | C10: Download a generated PDF (requires DOCUMENT.RENDER; DOCUMENT.VIEW-only is denied) | D10: Positive | E10: High | F10: Logged in as ORG_ADMIN. A generated-document row exists. | G10: 1. On /admin/documents, click the row's Download action. 2. Assert a PDF blob downloads. | H10: Generated document: INV-2026-0007 | I10: GET /api/v1/documents/uid/{uid}/download returns 200 application/pdf, Content-Disposition: attachment; filename='invoice-INV-2026-0007.pdf'. DOCUMENT.VIEW-only user: download returns 403. Cross-tenant uid: 403. | J10: /admin/documents | K10: DOCUMENT.RENDER | M10: Not Run
A11: PLAT-009 | B11: Document Templates | C11: Template registry lists + toggle a template status (DOCUMENT.TEMPLATE.MANAGE) | D11: Positive | E11: High | F11: Logged in as ORG_ADMIN. Seeded template registry rows exist. | G11: 1. Navigate to /admin/document-templates; list loads (full array, not paginated). 2. On the INVOICE row, change status to INACTIVE and edit the title. 3. Save; reload to verify change persisted. | H11: Template: INVOICE / TRANSACTIONAL_PDF; title: Tax Invoice | I11: GET /api/v1/documents/templates returns the template array. PUT /api/v1/documents/templates/{uid} returns 200 with updated DocumentTemplateDto. Status reflected. User without DOCUMENT.TEMPLATE.MANAGE → 403 on PUT and nav item hidden. | J11: /admin/document-templates | K11: DOCUMENT.TEMPLATE.MANAGE | M11: Not Run
A12: PLAT-010 | B12: Document Branding | C12: Edit the company branding profile (singleton — no uid in URL) | D12: Positive | E12: High | F12: Logged in as ORG_ADMIN (holds DOCUMENT.BRANDING.MANAGE). | G12: 1. Navigate to /admin/document-branding; the singleton profile loads into an edit form. 2. Edit display name, legal name, tax id, contact email. 3. Save; reload to verify values persisted. | H12: displayName: Acme Trading, legalName: Acme Trading Ltd, taxId: TIN-123456789, contactEmail: ar@acme.test | I12: PUT /api/v1/documents/branding returns 200 DocumentBrandingDto with updatedAt advanced. Changes persist on reload. Stale version returns conflict error. User without permission → 403; nav item hidden. | J12: /admin/document-branding | K12: DOCUMENT.BRANDING.MANAGE | M12: Not Run
A13: PLAT-011 | B13: Document Branding | C13: Updated branding is reflected in a freshly rendered document (visual check) | D13: Positive | E13: Medium | F13: Logged in as ORG_ADMIN. An invoice source exists. | G13: 1. Change the branding display name. 2. Render a new INVOICE. 3. Download and open the PDF. | H13: New display name: Updated Co Name | I13: The rendered PDF header shows the updated branding display name. Previously generated documents are unchanged (append-only log). This is a visual/manual verification. | J13: /admin/document-branding | K13: DOCUMENT.BRANDING.MANAGE | M13: Not Run

Sheet Platform – Notifications
A1: Platform – Notifications — UAT
A2: ID | B2: Area | C2: Test Scenario | D2: Type | E2: Priority | F2: Preconditions | G2: Steps | H2: Test Data | I2: Expected Result | J2: Route | K2: Permission | L2: Actual Result | M2: Status | N2: Severity | O2: Tester | P2: Run Date | Q2: Comments
A3: PLAT-012 | B3: Inbox | C3: In-app inbox lists the caller's notifications scoped to active company | D3: Positive | E3: High | F3: Logged in as ACCOUNTANT (holds NOTIFICATION.VIEW). Notifications addressed to this user exist. | G3: 1. Navigate to /admin/notifications. 2. Read rows: title, body, severity badge (INFO/WARNING/CRITICAL), created-at. | H3: ACCOUNTANT user with at least 3 notifications | I3: GET /api/v1/notifications returns 200 + meta. Only this user's company notifications shown. Severity badges are visually distinct. Paginator present. NO-PERMISSION user: forbidden. | J3: /admin/notifications | K3: NOTIFICATION.VIEW | M3: Not Run
A4: PLAT-013 | B4: Inbox | C4: Inbox unread filter and shell unread-count badge | D4: Positive | E4: Medium | F4: Logged in as ACCOUNTANT. Mix of read and unread notifications exist. | G4: 1. Toggle 'Unread only' filter on — only unread rows show; request carries unread=true. 2. Read the shell unread-count badge; cross-check against GET /api/v1/notifications/unread-count. | H4: Mix of read + unread notifications | I4: Filtered list shows only unread. Badge value equals UnreadCountDto.count. With zero unread: filter shows empty state; badge shows 0 or is hidden. Page resets to 0 on filter toggle. | J4: /admin/notifications | K4: NOTIFICATION.VIEW | M4: Not Run
A5: PLAT-014 | B5: Inbox | C5: Mark a single notification read; marking another user's notification is denied | D5: Positive | E5: High | F5: Logged in as ACCOUNTANT. An unread notification exists for this user. Another user's notification uid is known. | G5: 1. On /admin/notifications, click 'Mark read' on an unread row. 2. Assert the row flips to read and unread count decrements. 3. Attempt POST /api/v1/notifications/uid/{other-user-uid}/read. | H5: Own unread notification; another user's notification uid | I5: POST /api/v1/notifications/uid/{uid}/read returns 204. Row marked read; readAt set on next fetch. Another user's notification: 403 (recipient-is-me enforced by service, BR-NOTIF-04). Already-read row: no-op. | J5: /admin/notifications | K5: NOTIFICATION.VIEW | M5: Not Run
A6: PLAT-015 | B6: Inbox | C6: Mark all notifications read clears the unread count | D6: Positive | E6: Medium | F6: Logged in as ACCOUNTANT. Several unread notifications exist. | G6: 1. Click 'Mark all read'. 2. Observe toast. 3. Reload — unread count is 0. | H6: Multiple unread notifications | I6: POST /api/v1/notifications/read-all returns 204. All caller notifications marked read. Badge cleared. With no unread: no-op success. | J6: /admin/notifications | K6: NOTIFICATION.VIEW | M6: Not Run
A7: PLAT-016 | B7: Preferences | C7: Per-user notification preferences: list and upsert a preference (NOTIFICATION.PREFERENCE.MANAGE) | D7: Positive | E7: High | F7: Logged in as ACCOUNTANT (holds NOTIFICATION.PREFERENCE.MANAGE). Type catalogue seeded. | G7: 1. Navigate to /admin/notification-preferences; preferences load (plain array). 2. For typeKey LOW_STOCK, toggle muted=true and set channelsEnabled=IN_APP. 3. Save; reload to verify. | H7: typeKey: LOW_STOCK, muted: true, channelsEnabled: IN_APP | I7: PUT /api/v1/notification-preferences/{typeKey} returns 200 NotificationPreferenceDto. Preference persisted per-user scope. Unknown typeKey returns handled error. User without the permission: 403. | J7: /admin/notification-preferences | K7: NOTIFICATION.PREFERENCE.MANAGE | M7: Not Run
A8: PLAT-017 | B8: Admin Catalogue | C8: Admin notification type catalogue: list + toggle company state OFF (NOTIFICATION.ADMIN) | D8: Positive | E8: High | F8: Logged in as ORG_ADMIN (holds NOTIFICATION.ADMIN). Type catalogue seeded. | G8: 1. Navigate to /admin/notification-types; types load with displayName, audiencePermission, severity, companyEnabled. 2. Toggle typeKey LOW_STOCK company state to disabled (enabled=false). 3. Reload — companyEnabled: false. | H8: typeKey: LOW_STOCK | I8: PUT /api/v1/admin/notifications/types/{typeKey}/state returns 200 NotificationTypeDto. companyEnabled=false. Per-company scope — other companies unaffected. NOTIFICATION.VIEW-only user: 403 on toggle; nav item hidden. | J8: /admin/notification-types | K8: NOTIFICATION.ADMIN | M8: Not Run
